Workbook
Name Goal_State: Resultaten!#REF!
Name GoalState: Resultaten!#REF!

Sheet Toelichting
A1: Stelsel
A2: Deelnemer
A3: Datum

Sheet Strategie
A1: Strategie | C1: Vraag | D1: Waarom belangrijk? | E1: Score | F1: Relevant Logius | G1: Wat kan beter?
E2: Ambitie
A3: Governance | D3: De governance, bestuurlijke organisatie en besluitvorming is ingericht | E3: 5 | F3: 1
A4: G.1 | B4: Organisatiestructuur/ organisatiebeleid | C4: De organisatiestructuur is goed beschreven en onderbouwd. | D4: Als duidelijk is wie waarover beslist, werken partijen makkelijker samen. Zonder een heldere structuur ontstaat onduidelijkheid en discussie. | F4: 1
A5: G.2 | B5: Besluitvorming/ huishoudelijk regelement | C5: De besluitvormingsprocessen van de governance zijn beschreven waarbij het helder is welk gremium over welke onderwerpen gaat. | D5: Als niemand weet hoe en door wie besluiten genomen worden, ontstaat onduidelijkheid of conflicten. Duidelijke regels voorkomen dat. | F5: 1
A6: G.3 | B6: Deelname | C6: Een procedure is aanwezig voor het laten deelnemen van organisaties aan de governance. | D6: Als niet duidelijk is hoe je kunt meedoen aan de governance, blijven organisaties buiten de deur. Een heldere procedure maakt de deelname laagdrempelig. | F6: 1
A7: G.5 | B7: Escalatie | C7: De escalatieprocedures en lijnen zijn beschikbaar. | D7: Het is duidelijk waar de kwestie voor besluitvorming kan worden voorgelegd indien partijen er niet onderling uitkomen. | F7: 1
A8: G.6 | B8: Stakeholdersbetrokkenheid | C8: Het is duidelijk waar welke belanghebbenden moeten deelnemen en welke rol zij dienen te vervullen. | D8: De stakeholders kunnen optimaal hun achterban bereiken en vertegenwoordigen. Daarmee zijn ze waardevol om draagvlak te creëren binnen de governance. | F8: 1
A9: G.8 | B9: Vastlegging afspraken | C9: De doelstellingen, resultaten en werkafspraken zijn vastgelegd en door de stakeholders en overige betrokkenen ondertekend/bekrachtigd. De gekozen vorm van vastlegging is daarbij passend voor alle betrokkenen. | D9: Een gedeelde missie zorgt voor goede samenwerking. Leg doelen en afspraken daarom vroeg vast en laat alle partijen dit formeel bevestigen. | F9: 1
A10: G.9 | B10: Stakeholderanalyse | C10: Een stakeholder-analyse is uitgevoerd en vastgelegd. De analyse wordt periodiek herhaald om eventuele wijzigingen tijdig te onderkennen. | D10: Een stakeholder-analyse opstellen is verstandig en in complexe situaties een must. Voor de goverance is het van belang goed inzicht in het speelveld te hebben en daarmee de verbinding te organiseren. | F10: 1
A11: Visie | D11: Er is een inhoudelijke visie opgesteld over de richting van de ontwikkeling. | E11: 5
A12: V.1 | B12: Visie | C12: Er is een duidelijk geëxpliciteerde visie over de bovenliggende doelstellingen en de bijdrage daaraan van het stelsel beschikbaar. | F12: 1
A13: V2 | B13: Draagvlak | C13: De visie wordt actief gedeeld met de omgeving. De goverance organiseert draagvlak mbt visie. | D13: De visiedocumenten zijn publiek beschikbaar. De boodschap staat bijvoorbeeld op de site van een afsprakenstelsel. | F13: 1
A14: V4 | B14: Meebewegen | C14: De visie anticipeert op relevante technologische, maatschappelijke en juridische ontwikkelingen en bevat een strategie om hierop in te spelen. | D14: Een volwassen standaard of afsprakenstelsel heeft een visie die niet alleen de huidige situatie adresseert, maar ook anticipeert op toekomstige ontwikkelingen zoals nieuwe technologieën, veranderende gebruikersbehoeften, wijzigingen in wet- en regelgeving en maatschappelijke trends. | F14: 1
A15: Business Case | D15: De business case is opgesteld en wordt onderhouden en op gestuurd. | E15: 5
A16: BC.1 | B16: Business Case | C16: Er is een goed inzicht in de te bereiken voordelen/benefits en de daarvoor benodigde inspanning/kosten. | F16: 1
A17: BC.3 | B17: Transparantie | C17: De business case is transparant en wordt actief gebruikt in de besluitvorming over doorontwikkeling en investeringen in het stelsel | D17: In een volwassen afsprakenstelsel worden beslissingen over nieuwe functionaliteiten, wijzigingen of investeringen expliciet getoetst aan de business case, waarbij wordt gekeken naar de impact op de verwachte kosten en baten voor alle betrokken partijen. | F17: 1
A18: BC.4 | B18: Benefits management | C18: De governance stuurt concreet op het realiseren van maatschappelijke waarde van het stelsel. | D18: Gerichte sturing op de benefits borgt de daadwerkelijke realisatie daarvan. Wie er dient te sturen is sterk afhankelijk van de context. Programma management raamwerken zoals MSP bieden hiervoor voldoende handvatten. | F18: 1
A19: Financiën | D19: Een financieel model voor de lange termijn garandeert dat de opbrengsten in overeenstemming zijn met de behoeften. | E19: 5
A20: F.1 | B20: Structureel financieel model | C20: Structurele financiering voor de komende 2 tot 3 jaar is voor het afsprakenstelsel geregeld. | D20: Er moet een structureel financieringsmodel beschreven zijn dat realistische garanties geeft dat er jaarlijks structureel voldoende budget is om op zijn minst het stelsel te onderhouden. Een eenmalige subsidie voldoet dus zeker niet hieraan. | F20: 1
A21: F.2 | B21: Behoefteanalyse | C21: De structurele financiering is gebaseerd op een grondige behoefte analyse voor het beheren en doorontwikkelen van het afsprakenstelsel. | D21: Breng in kaart wat voor financiële behoefte het stelsel heeft. Houd hierbij ook rekening met de verwachtingen van stakeholders. Als er met een meerjarenbegroting wordt gerekend moet deze gebaseerd zijn op structurele inkomsten. | F21: 1
A22: F.3 | B22: Toekomstbestendigheid | C22: Het financieringsmodel is toekomstbestendig en kan meegroeien met het aantal deelnemers. | D22: Een goed financieringsmodel voor een afsprakenstelsel moet de volgende eigenschappen hebben: Proportionaliteit/ Flexibiliteit/ Evenwichtige verdeling / Voorspelbaarheid. | F22: 1
A23: Toezicht | D23: Van toepassing voor afsprakenstelsels; wie controleert op de spelregels? | E23: 5
A24: T.1 | B24: Toezichthouder | C24: Het afsprakenstelsel heeft een duidelijk gedefinieerde toezichthouder met formeel vastgelegde bevoegdheden en verantwoordelijkheden; hiermee is de toezichthouder onafhankelijk. | D24: Binnen een afsprakenstelsels bestaat in de ideale situatie een onafhankelijke toetsende derde met voldoende middelen om in te grijpen bij niet naleving. | F24: 1
A25: T.2 | B25: Mandaat | C25: De toezichthouder heeft voldoende instrumenten en mandaat rond het uitvoeren van toezichttaken en de naleving van de eisen door de deelnemers binnen het afsprakenstelsel. | D25: Het is niet alleen kwantiteit maar ook kwaliteit van de instrumenten. Er is een goede verhouding nodig tussen zachte instrumenten tot en met hard ingrijpen zoals een boete of verwijdering. | F25: 1
A26: T.4 | B26: Escalatie | C26: Er is een transparant en gedocumenteerd escalatieproces voor het melden van niet-naleving van afspraken. | F26: 1

Sheet Tactiek
A1: Tactiek | C1: Vraag | D1: Waarom belangrijk? | E1: Score | F1: Relevant Logius | G1: Wat kan beter?
E2: Ambitie
A3: Werkgroepen | D3: De juiste stakeholders participeren in de community en de juiste samenstelling wordt bewaakt. | E3: 5 | F3: 3
A4: C.1 | B4: Ambities en doelstellingen | C4: De ambities en doelstellingen van de werkgroep zijn formeel vastgelegd. | D4: Als niet vastligt wat een werkgroep wil bereiken, werken groepen langs elkaar heen of dekken ze niet alles af. Heldere doelen per werkgroep voorkomen dat. | F4: 5
A5: C.2 | B5: Werkgroep organisatie | C5: De rollen en verantwoordelijkheden binnen de werkgroep zijn gedefinieerd zoals wie de voorzitter of eigenaar is. | D5: Een succesvolle werkgroep kenmerkt zich o.a. door duidelijk belegde rollen en verantwoordelijkheden. | F5: 3
A6: C.3 | B6: Werkgroep samenstelling | C6: Alle belangrijke partijen zijn goed vertegenwoordigd in de werkgroep, en er zijn manieren om hen actief te laten meedoen | D6: Er is een adoptiestrategie ontwikkeld die gericht is op het vergroten van het draagvlak voor het afsprakenstelsel. | F6: 3
A7: Adoptie & Erkenning | D7: Er is een strategie om adoptie van het afsprakenstelsel te verhogen. | E7: 5 | F7: 3
A8: AE.1 | B8: Adoptiestrategie | C8: Er is een adoptiestrategie: een plan om het gebruik van het stelsel te vergroten. | D8: Zonder actief plan blijft gebruik vaak achter. Wetgeving of convenanten helpen het meest, maar ook zonder dat kan een goede strategie adoptie stimuleren. | F8: 3
A9: AE.3 | B9: Adoptie-instrument | C9: Het is duidelijk welke middelen adoptie kunnen bevorderen (juridisch, financieel, communicatief), en de gekozen middelen worden ook echt ingezet. | D9: Er zijn drie soorten middelen: juridisch, financieel en communicatief. Verplichten werkt het sterkst. Is de kans op gebruik al hoog? Dan is goede communicatie vaak genoeg. | F9: 3
A10: AE.4 | B10: Referentie-implementatie | C10: Er bestaat een referentie-implementatie om de verschillende stakeholders te overtuigen van de meerwaarde van het stelsel. | D10: Een referentie-implementatie is een middel om de werking en praktische haalbaarheid van een stelsel aan te tonen en helpt om de drempel voor gebruik te verlagen. | F10: 3
A11: Architectuur | D11: De samenhang van inhoudelijke producten is op hoofdlijnen getoetst en geformaliseerd in een roadmap. | E11: 5 | F11: 3
A12: A.1 | B12: Architectuur | C12: De volledige architectuur van het stelsel is beschreven. | D12: Zonder een compleet architectuurplaatje mis je afhankelijkheden met andere stelsels en standaarden, en is niet duidelijk wat het stelsel wel en niet dekt. | F12: 3
A13: A.2 | B13: Inhoudelijke samenhang vastleggen | C13: De relatie en afhankelijkheden met andere stelsels en standaarden zijn volledig in kaart gebracht. | D13: Stelsels kunnen elkaar versterken of afhankelijk zijn. Deze relaties moeten duidelijk zijn. | F13: 3
A14: A.3 | B14: Afstemmingsplan | C14: Er is waar nodig afstemming met vertegenwoordigers van overige afsprakenstelsels en standaarden. Dat kan ook internationaal. | D14: In het geval van relaties of afhankelijkheden helpt het om elkaar op de hoogte en daar waar nodig af te stemmen om veranderingen goed te kunnen managen. | F14: 3
A15: Roadmapping | E15: 5 | F15: 3
A16: RM.1 | B16: Jaarplan/Ontwikkelagenda | C16: Er is een roadmap of plan opgesteld ﻿waarmee invulling wordt gegeven aan de visie van het stelsel. Deze roadmap maakt duidelijk welke ontwikkeling op welk moment in de tijd gerealiseerd gaat worden. | D16: De roadmap vormt de basis wanneer verbeteringen beschikbaar komen. Dit biedt houvast voor gebruikers wanneer ze zelf moeten investeren en zicht in de mogeljike opbrengsten. | F16: 3
A17: Risicoanalyse | E17: 5 | F17: 3
A18: RA.1 | B18: Risicoanalyse | C18: Er is een periodiek uitgevoerd risicoanalyseproces dat zowel strategische, tactische als operationele risico's voor het afsprakenstelsel identificeert, analyseert en evalueert | D18: Denk aan een jaarlijks uitgevoerde stelselrisico met de deelnemers binnen het stelsel. Dit is een analyse die zich richt op wat er mis kan gaan en maatregelen om de kans of impact van het risico te verkleinen.
A19: RA.2 | B19: Kader | C19: Er bestaat een kader met normen rond informatiebeveiliging die van toepassing is op de geleverde diensten door de deelnemers binnen het afsprakenstelsel. | D19: Vertrouwen van gebruikers is cruciaal voor het succes van het stelsel. Kaders voor informatiebeveiliging zorgen voor veilige dienstverlening en geven de toezichthouder iets om op te toetsen.
A20: RA.3 | B20: Plan do check act cyclus rond risico's is ingeregeld. | C20: De resultaten van de stelselrisicoanalyse maken onderdeel uit van een "plan do check act"- cyclus. De resultaten worden gedeeld met de governance.

Sheet Operationeel
A1: Operationeel | C1: Vraag | D1: Waarom belangrijk? | E1: Score | F1: Relevant Logius | G1: Wat kan beter?
A2: Initiatie | D2: De activiteiten behorende bij het identificeren van nieuwe ideeën zijn opgetuigd. | E2: Ambitie | F2: 4
E3: 5
A4: Wensen & eisen | D4: Maintenance Requests (MRs) worden opgesteld bij wensen en eisen. | E4: 5 | F4: 1
A5: WE.1 | B5: MR-management | C5: Een publiek toegankelijk platform is beschikbaar waarbij wensen en eisen kunnen worden ingediend en waarvan de afhandeling kan worden gemonitord. | D5: Website met historie, publiek toegankelijk. Toegekend aan versie. Formele consultatie. Workshops of discussiebijeenkomsten. Onderscheid maken tussen fixes, en nieuwe zaken. | F5: 1
A6: WE.3 | B6: Proces | C6: Er is een transparant en toegankelijk proces voor het indienen, beoordelen en prioriteren van wensen en eisen door alle stakeholders. | D6: Als iedereen weet hoe wensen worden ingediend, beoordeeld en geprioriteerd, kunnen stakeholders actief meedenken over de doorontwikkeling van het stelsel.
A7: Ontwikkeling | D7: Aanpassingen worden technologie onafhankelijk en op conceptueel niveau uitgewerkt. | E7: 5 | F7: 1
A8: ON.1 | B8: Ontwikkelingscheiding | C8: Wijzigingen worden eerst conceptueel getoetst voordat ze technisch geïmplementeerd worden. | D8: Als je een wijziging meteen technisch bouwt zonder 'm eerst goed te doordenken, loop je het risico op problemen die je vooraf had kunnen zien. | F8: 1
A9: ON.2 | B9: Specificaties | C9: De specificaties, documentatie en hulpmiddelen voor implementatie zijn publiek beschikbaar en actueel. | D9: Als specificaties en hulpmiddelen niet vrij toegankelijk zijn, kunnen stakeholders niet goed of correct implementeren.
A10: ON.3 | B10: Versiebeheer | C10: Er is een gestructureerd changemanagementproces ingericht, inclusief versiebeheer en uitfasering van oude versies. | D10: Alle wijzigingen doorlopen een formeel wijzigingsproces, waarbij duidelijk is hoe voorstellen worden ingediend, beoordeeld, getest en geïmplementeerd. Er is beleid voor versiebeheer (major/minor/bugfixes) en voor het uitfaseren van verouderde versies. | F10: 1
A11: Uitvoering | D11: Veranderingen in de specificatie worden vanuit conceptuele oplossingen uitgevoerd. | E11: 5 | F11: 1
A12: U.1 | B12: Conceptuele oplossingen | C12: Een aanpassing aan het stelsel wordt eerst zorgvuldig ontworpen en getoetst voordat deze definitief wordt ingevoerd. | D12: Zorg ervoor dat klachten en incidenten niet de roadmap gaan sturen. Kleine veranderingen kunnen volgens de normale gang van zaken worden ingepland. Grote veranderingen kunnen waar nodig prioriteit krijgen, maar alleen na beoordeling van de sturende gremia. | F12: 1
A13: Documentatie | D13: Het primaire beheerproces wordt gedocumenteerd en is voor iedereen inzichtelijk. | E13: 5 | F13: 1
A14: D.1 | B14: Specificatie vrij beschikbaar | C14: Specificaties van het stelsel zijn beschikbaar en publiek toegankelijk. | D14: Zonder vrij toegankelijke specificaties en hulpmiddelen kan niemand het stelsel correct implementeren. | F14: 1
A15: D.2 | B15: Openbaarheid documenten | C15: Alle relevante documenten zijn publiek toegankelijk. | D15: Het is belangrijk om alle documenten waar geen expliciete vertrouwelijkheid op rust, openbaar aan te bieden. Transparantie is een belangrijjke kernwaarde om draagvlak te realiseren. Op deze manier kan iedereen aan het afsprakenstelsel meewerken en meedenken. | F15: 1
A16: D.3 | B16: Documentatie beheerproces | C16: Het beheerproces is gedocumenteerd en publiek toegankelijk. | D16: Er is documentatie met de beheerprocessen zoals een operationeel handboek waarbij de benodigde (ITIL) processen zijn beschreven. | F16: 1

Sheet Implementatie Ondersteuning
A1: Implementatie Ondersteuning | C1: Vraag | D1: Waarom belangrijk? | E1: Score | F1: Relevant Logius 1=ja, 2=nee, 3=aanpassing, 4=later 5=nieuw | G1: Wat kan beter?
E2: Ambitie
A3: Opleiding | D3: Er worden opleidingsmogelijkheden geboden aan verschillende gebruikersgroepen. | E3: 5 | F3: 1
A4: O.1 | B4: Opleidingsaanbod | C4: Er worden opleidingsmogelijkheden geboden aan verschillende gebruikersgroepen. | D4: Denk aan opleidingsmateriaal of een training/cursus. | F4: 1
A5: Ondersteuning | D5: Er is een hulp beschikbaar die partijen die implemeren op weg kan helpen. | E5: 5
A6: H.1 | B6: Helpdesk-functie | C6: Er is een helpdeskfunctie beschikbaar voor deelnemers en belanghebbenden. Je kan hier verstoringen melden en vragen stellen. | D6: Dat kan ook ingevuld zijn met een infobox. | F6: 3
A7: H.2 | B7: Bereikbaarheid | C7: De helpdesk is bereikbaar via meerdere kanalen en deze kanalen zijn duidelijk gecommuniceerd aan alle stakeholders. | D7: Borgt laagdrempelige toegang tot ondersteuning.
A8: Module Ontwikkeling | E8: 5
A9: MO.2 | B9: Modules en libraries | C9: Het afsprakenstelsel is in staat om verschillende stakeholders goed te bedienen met modules en libraries. | D9: Denk aan het aanbieden van een open implementatie, validator software, API’s/libraries voor test en ontwikkelwerkzaamheden om eigen implementatie te maken. | F9: 1
A10: Pilot/vernieuwing | E10: 5
A11: P.1 | B11: Vernieuwing | C11: Het afsprakenstelsel is in staat om te innoveren. | D11: Vernieuwen is een integraal onderdeel van het ontwerp van een afsprakenstelsel.
A12: P.2 | B12: Vernieuwingsproces | C12: Het proces voor vernieuwing met de bijbehorende beoordelingscriteria is beschreven. | D12: Een procesbeschrijving helpt dat het stelsel in staat is nieuwe ontwikkelingen tijdig te signaleren, te beoordelen op de mogelijke waarde voor het stelsel, te toetsen en eventueel te implementeren.
A13: Validatie & Certificatie | D13: Validaties en certificering toetsen de correctheid van implementaties. | E13: 5
A14: VC.1 | B14: Validatie service | C14: Een validatieservice is aanwezig. | D14: Het aanbieden van validatie service (via helpdesk, online omgeving), adoptie werkt bevorderend. | F14: 1
A15: VC.2 | B15: Inspectie en/of toetsing | C15: Inspecties en toetsingen zijn ingeregeld. | D15: Denk aan inspecties, toetsingen van derden en een ‘eigen verklaring’ van conformiteit Test de (individuele) implementaties, bijvoorbeeld door een certificeringsprogramma op te stellen voor deelnemende leveranciers. | F15: 1

Sheet Communicatie
A1: Communicatie | C1: Vraag | D1: Waarom belangrijk? | E1: Score | F1: Relevant Logius | G1: Wat kan beter?
A2: Promotie | D2: Het nut/noodzaak/voordeel van het afsprakenstelsel wordt actief uitgedragen | E2: 5 | F2: 1
A3: PR.1 | B3: Promotiestrategie/ communicatieplan/ marketingplan | C3: Een op de verschillende doelgroepen afgestemd communicatieplan is beschikbaar en wordt uitgevoerd. | D3: De uitdaging blijft: hoe vermarkt ik het stelsel? Dit is niet anders dan bij “gewone” producten. De klassieke marketing aanpak kan ook voor een stelsel gebruikt worden. | F3: 1
A4: PR.2 | B4: Duidelijke uitleg | C4: Er is een voor alle doelgroepen begrijpelijke en goed vindbare toelichting beschikbaar | D4: Een animatie of filmpje op een website kan binnen enkele minuten duidelijkheid geven over de diensten van een stelsel. Zo ook wat het concreet voor gebruikers inhoudt.
A5: PR.4 | B5: Draag voordelen van het stelsel uit | C5: Het nut/noodzaak/voordeel van het stelsel wordt actief uitgedragen | D5: Draag op elk niveau de voordelen van stelsel uit. Weet wat de markt beweegt en welk probleem het oplost. | F5: 1
A6: Publicatie | D6: Informatie over afsprakenstelsel is goed vindbaar op internet. | E6: 5 | F6: 1
A7: PU.1 | B7: Zorg voor een voor iedereen toegankelijk platform voor communicatie en informatie | C7: Meerdere kanalen/platforms worden benut voor de communicatie naar de verschillende doelgroepen. | D7: De website voldoet aan de Digitoegankelijk richtlijnen. Deze site bevat nieuws over de ontwikkeling, adoptie en doelen van het stelsel. De website bevat instructies hoe men aan de volle specificaties komt. Verder moeten communicatielijnen duidelijk zijn, zowel voor vaste bezoekers als voor nieuw geïnteresseerde bezoekers. | F7: 1
A8: PU.2 | B8: Logische plek voor communicatie | C8: Er is een publiek toegankelijke, goed vindbare en gebruiksvriendelijke website of platform waarop alle relevante informatie, nieuws, documentatie en updates over het stelsel/standaard worden gepubliceerd. | D8: Borgt transparantie, vindbaarheid en laagdrempelige toegang tot informatie voor bestaande en potentiële gebruikers.
A9: PU.4 | B9: Publicatieprocedure | C9: Er is een procedure voor het publiceren van nieuwe versies, updates en belangrijke besluiten, inclusief tijdige aankondiging en duidelijke uitleg van de impact. | D9: Borgt voorspelbaarheid en transparantie bij wijzigingen
A10: Klachtenafhandeling | D10: Klachten worden zorgvuldig behandeld en gebruikt in verbeteringstrajecten. | E10: 5 | F10: 1
A11: KL.1 | B11: Bezwaar- en klachtenprocedure | C11: Er bestaat een procedure wie klachten kan indienen en hoe deze behandeld worden. | D11: Iedere belanghebbende kan formeel bezwaar aantekenen tegen de gevolgde procedure. Daarnaast kan informeel een klacht ingediend worden over de gevolgde procedure. | F11: 1
A12: KL.3 | B12: Van klacht naar verbetering | C12: Er is een systematische registratie en analyse van klachten, waarbij trends en structurele knelpunten worden gesignaleerd en deze informatie wordt ingezet voor het continu verbeteren van processen, producten of dienstverlening.

Sheet Open
A1: Eisen | B1: Ontwikkelaar | C1: Inplementator | D1: Gebruiker | F1: kan bij stakeholdermanagement. Als je een open stelsel bent dan zijn dit de zaken die je moet volgen.
A3: 1. Open Meeting | B3: X
A5: 2. Consensus | B5: X
A7: 3. Due Process | B7: X
A9: 4. One World | B9: X | C9: X | D9: X
A11: 5. Open IPR | B11: X | C11: X | D11: X
A13: 6. Open Change | B13: X | C13: X | D13: X
A15: 7. Open Documents | C15: X | D15: X
A17: 8. Open Interface | C17: X | D17: X
A19: 9. Open Access | C19: X | D19: X
A21: 10. Ongoing Support | D21: X

Sheet Resultaten
B1: Resultaten Selfassessment BOMOS
B3: =Strategie!$A$1 -> Strategie | C3: (Gemiddelde) Huidige positie | D3: Ambitie | E3: Gap | F3: Gap | G3: Strategie | O3: Totaal
B4: =Strategie!$A$3 -> Governance | C4: =IFERROR(AVERAGE(_output!C3:C9),"") | D4: =Strategie!E3 -> 5 | E4: =D4-C4 -> #VALUE! | F4: =D4-C4 -> #VALUE!
B5: =Strategie!$A$11 -> Visie | C5: =IFERROR(AVERAGE(_output!C17:C19),"") | D5: =Strategie!E11 -> 5 | E5: =D5-C5 -> #VALUE! | F5: =D5-C5 -> #VALUE!
B6: =Strategie!A15 -> Business Case | C6: =IFERROR(AVERAGE(_output!C22:C24),"") | D6: =Strategie!E15 -> 5 | E6: =D6-C6 -> #VALUE!
B7: =Strategie!$A$19 -> Financiën | C7: =IFERROR(AVERAGE(_output!C27:C29),"") | D7: =Strategie!E19 -> 5 | E7: =D7-C7 -> #VALUE! | F7: =D7-C7 -> #VALUE!
B8: =Strategie!$A$23 -> Toezicht | C8: =IFERROR(AVERAGE(_output!C12:C14),"") | D8: =Strategie!E23 -> 5 | E8: =D8-C8 -> #VALUE!
B9: Niveau | C9: =AVERAGE(C4:C7) -> #DIV/0! | D9: =AVERAGE(D4:D7) -> 5 | E9: =D9-C9 -> #DIV/0! | F9: =D9-C9 -> #DIV/0!
B10: 5
B11: =Tactiek!$A$1 -> Tactiek | C11: (Gemiddelde) Huidige positie | D11: Ambitie | E11: Gap | F11: Gap | G11: Tactiek
B12: =Tactiek!A3 -> Werkgroepen | C12: =IFERROR(AVERAGE(_output!C32:C34),"") | D12: =Tactiek!E3 -> 5 | E12: =D12-C12 -> #VALUE!
B13: =Tactiek!A7 -> Adoptie & Erkenning | C13: =IFERROR(AVERAGE(_output!C37:C39),"") | D13: =Tactiek!E7 -> 5 | E13: =D13-C13 -> #VALUE!
B14: =Tactiek!A11 -> Architectuur | C14: =IFERROR(AVERAGE(_output!C42:C44),"") | D14: =Tactiek!E11 -> 5 | E14: =D14-C14 -> #VALUE!
B15: =Tactiek!A17 -> Risicoanalyse | C15: =IFERROR(AVERAGE(_output!C50:C52),"") | D15: =Tactiek!E17 -> 5 | E15: =D15-C15 -> #VALUE!
B16: =Tactiek!A15 -> Roadmapping | C16: =IFERROR(AVERAGE(_output!C47:C47),"") | D16: =Tactiek!E15 -> 5 | E16: =D16-C16 -> #VALUE!
B17: Niveau | C17: =AVERAGE(C12:C16) -> #DIV/0! | D17: =AVERAGE(D13:D16) -> 5 | E17: =D17-C17 -> #DIV/0!
B19: =Operationeel!A1 -> Operationeel | C19: (Gemiddelde) Huidige positie | D19: Ambitie | E19: Gap | F19: Gap | G19: =Operationeel!A1 -> Operationeel
B20: =Operationeel!A4 -> Wensen & eisen | C20: =IFERROR(AVERAGE(_output!C55:C56),"") | D20: =Operationeel!E4 -> 5 | E20: =D20-C20 -> #VALUE!
B21: =Operationeel!A7 -> Ontwikkeling | C21: =IFERROR(AVERAGE(_output!C59:C61),"") | D21: =Operationeel!E7 -> 5 | E21: =D21-C21 -> #VALUE!
B22: =Operationeel!A11 -> Uitvoering | C22: =IFERROR(AVERAGE(_output!C64:C64),"") | D22: =Operationeel!E11 -> 5 | E22: =D22-C22 -> #VALUE!
B23: =Operationeel!A13 -> Documentatie | C23: =IFERROR(AVERAGE(_output!C67:C69),"") | D23: =Operationeel!E13 -> 5 | E23: =D23-C23 -> #VALUE!
B24: Niveau | C24: =AVERAGE(C20:C23) -> #DIV/0! | D24: =AVERAGE(D21:D23) -> 5 | E24: =D24-C24 -> #DIV/0!
B26: ='Implementatie Ondersteuning'!$A$1 -> Implementatie Ondersteuning | C26: (Gemiddelde) Huidige positie | D26: Ambitie | E26: Gap | F26: Gap | G26: =B26 -> Implementatie Ondersteuning
B27: ='Implementatie Ondersteuning'!A3 -> Opleiding | C27: =IFERROR(AVERAGE(_output!C72:C72),"") | D27: ='Implementatie Ondersteuning'!E3 -> 5 | E27: =D27-C27 -> #VALUE!
B28: ='Implementatie Ondersteuning'!A5 -> Ondersteuning | C28: =IFERROR(AVERAGE(_output!C75:C76),"") | D28: ='Implementatie Ondersteuning'!E5 -> 5 | E28: =D28-C28 -> #VALUE!
B29: ='Implementatie Ondersteuning'!A8 -> Module Ontwikkeling | C29: =IFERROR(AVERAGE(_output!C79:C79),"") | D29: ='Implementatie Ondersteuning'!E8 -> 5 | E29: =D29-C29 -> #VALUE!
B30: ='Implementatie Ondersteuning'!A10 -> Pilot/vernieuwing | C30: =IFERROR(AVERAGE(_output!C82:C83),"") | D30: ='Implementatie Ondersteuning'!E10 -> 5 | E30: =D30-C30 -> #VALUE!
B31: ='Implementatie Ondersteuning'!A13 -> Validatie & Certificatie | C31: =IFERROR(AVERAGE(_output!C86:C87),"") | D31: ='Implementatie Ondersteuning'!E13 -> 5 | E31: =D31-C31 -> #VALUE!
B32: Niveau | C32: =AVERAGE(C27:C31) -> #DIV/0! | D32: =AVERAGE(D28:D30) -> 5 | E32: =D32-C32 -> #DIV/0!
B34: =Communicatie!$A$1 -> Communicatie | C34: (Gemiddelde) Huidige positie | D34: Ambitie | E34: Gap | F34: Gap | G34: =B34 -> Communicatie
B35: =Communicatie!$A$2 -> Promotie | C35: =IFERROR(AVERAGE(_output!C90:C92),"") | D35: =Communicatie!E2 -> 5 | E35: =D35-C35 -> #VALUE!
B36: =Communicatie!$A$6 -> Publicatie | C36: =IFERROR(AVERAGE(_output!C95:C97),"") | D36: =Communicatie!E6 -> 5 | E36: =D36-C36 -> #VALUE!
B37: =Communicatie!$A$10 -> Klachtenafhandeling | C37: =IFERROR(AVERAGE(_output!C100:C101),"") | D37: =Communicatie!E10 -> 5 | E37: =D37-C37 -> #VALUE!
B38: Niveau | C38: =AVERAGE(C35:C37) -> #DIV/0! | D38: =AVERAGE(D36:D37) -> 5 | E38: =D38-C38 -> #DIV/0!

Sheet _invoervelden
A1: Vraagtype | C1: Antwoordopties | D1: Antwoordopties
A3: Yes/No | B3: 1 | C3: No | D3: Nee
B4: 2 | C4: Yes | D4: Ja
A5: optional | B5: 3 | C5: Not required | D5: Niet van toepassing
A7: Yes/No/Unknown | C7: answer options
B8: 1 | C8: No | D8: Nee
B9: 2 | C9: Unknown | D9: Niet bekend
B10: 3 | C10: Yes | D10: Ja
B11: 4 | C11: Not required | D11: Niet van toepassing
A13: Detailed | B13: 1 | C13: No | D13: Niet
B14: 2 | C14: Partially | D14: Beperkt
B15: 3 | C15: Averagely | D15: Gemiddeld / Redelijk
B16: 4 | C16: Mostly | D16: Overwegend
B17: 5 | C17: Fully | D17: Volledig
A18: Optional | B18: 6 | C18: Not required | D18: Niet van toepassing
A20: Completeness | B20: 1 | C20: Incomplete | D20: Niet
B21: 2 | C21: Partially complete | D21: Beperkt
B22: 3 | C22: Averagely complete | D22: Redelijk compleet
B23: 4 | C23: Mostly complete | D23: Vrijwel compleet
B24: 5 | C24: Fully complete | D24: Volledig
B25: 6 | D25: Niet van toepassing
A26: Importance | B26: 1 | C26: None | D26: Niet
B27: 2 | C27: Low | D27: Laag
B28: 3 | C28: Normal | D28: Gemiddeld
B29: 4 | C29: High | D29: Hoog
B30: 5 | C30: Critical | D30: Kritisch
A32: Weighing | B32: 1 | C32: x1
B33: 2 | C33: x2
B34: 3 | C34: x3
B35: 4 | C35: x4
B36: 5 | C36: x5
A38: Occurrence | B38: 1 | C38: Never | D38: Nooit
B39: 2 | C39: Sometimes | D39: Soms
B40: 3 | C40: Averagely | D40: Regelmatig
B41: 4 | C41: Mostly | D41: Vaak
B42: 5 | C42: Always | D42: Altijd
B43: 6 | D43: Niet van toepassing
A44: Satisfaction | B44: 1 | C44: No | D44: Niet
B45: 2 | C45: Somewhat | D45: Beperkt
B46: 3 | C46: Averagely | D46: Gemiddeld
...

Sheet _output
A1: Assessmentvraag per onderdeel | B1: Antwoord | C1: Score (houdt rekening met 'niet van toepassing')
A2: Governance | C2: =IFERROR(AVERAGE(C3:C9),"NIET") -> NIET
A3: G.1 | B3: 6 | C3: =IF(B3=6,"",IF(B3="","",B3))
A4: G.2 | B4: 6 | C4: =IF(B4=6,"",IF(B4="","",B4))
A5: G.3 | B5: 6 | C5: =IF(B5=6,"",IF(B5="","",B5))
A6: G.5 | B6: 6 | C6: =IF(B6=6,"",IF(B6="","",B6))
A7: G.6 | B7: 6 | C7: =IF(B7=6,"",IF(B7="","",B7))
A8: G.8 | B8: 6 | C8: =IF(B8=6,"",IF(B8="","",B8))
A9: G.9 | B9: 6 | C9: =IF(B9=6,"",IF(B9="","",B9))
A11: Toezicht | C11: =IFERROR(AVERAGE(C12:C14),"NIET") -> NIET
A12: T.1 | B12: 6 | C12: =IF(B12=6,"",IF(B12="","",B12))
A13: T.2 | B13: 6 | C13: =IF(B13=6,"",IF(B13="","",B13))
A14: T.4 | B14: 6 | C14: =IF(B14=6,"",IF(B14="","",B14))
A16: Visie | C16: =IFERROR(AVERAGE(C17:C19),"NIET") -> NIET
A17: V.1 | B17: 6 | C17: =IF(B17=6,"",IF(B17="","",B17))
A18: V2 | B18: 6 | C18: =IF(B18=6,"",IF(B18="","",B18))
A19: V4 | B19: 6 | C19: =IF(B19=6,"",IF(B19="","",B19))
A21: Business case | C21: =IFERROR(AVERAGE(C22:C24),"NIET") -> NIET
A22: BC.1 | B22: 6 | C22: =IF(B22=6,"",IF(B22="","",B22))
A23: BC.3 | B23: 6 | C23: =IF(B23=6,"",IF(B23="","",B23))
A24: BC.4 | B24: 6 | C24: =IF(B24=6,"",IF(B24="","",B24))
A26: Financiën | C26: =IFERROR(AVERAGE(C27:C29),"NIET") -> NIET
A27: F.1 | B27: 6 | C27: =IF(B27=6,"",IF(B27="","",B27))
A28: F.2 | B28: 6 | C28: =IF(B28=6,"",IF(B28="","",B28))
A29: F.3 | B29: 6 | C29: =IF(B29=6,"",IF(B29="","",B29))
A31: =Tactiek!A3 -> Werkgroepen | C31: =IFERROR(AVERAGE(C32:C34),"NIET") -> NIET
A32: C.1 | B32: 6 | C32: =IF(B32=6,"",IF(B32="","",B32))
A33: C.2 | B33: 6 | C33: =IF(B33=6,"",IF(B33="","",B33))
A34: C.3 | B34: 6 | C34: =IF(B34=6,"",IF(B34="","",B34))
A36: =Tactiek!A7 -> Adoptie & Erkenning | C36: =IFERROR(AVERAGE(C37:C39),"NIET") -> NIET
A37: AE.1 | B37: 6 | C37: =IF(B37=6,"",IF(B37="","",B37))
A38: AE.3 | B38: 6 | C38: =IF(B38=6,"",IF(B38="","",B38))
A39: AE.4 | B39: 6 | C39: =IF(B39=6,"",IF(B39="","",B39))
A41: =Tactiek!A11 -> Architectuur | C41: =IFERROR(AVERAGE(C42:C44),"NIET") -> NIET
A42: A.1 | B42: 6 | C42: =IF(B42=6,"",IF(B42="","",B42))
A43: A.2 | B43: 6 | C43: =IF(B43=6,"",IF(B43="","",B43))
A44: A.3 | B44: 6 | C44: =IF(B44=6,"",IF(B44="","",B44))
A46: =Tactiek!A15 -> Roadmapping | C46: =IFERROR(AVERAGE(C47:C47),"NIET") -> NIET
A47: RM.1 | B47: 6 | C47: =IF(B47=6,"",IF(B47="","",B47))
A49: =Tactiek!A17 -> Risicoanalyse | C49: =IFERROR(AVERAGE(C50:C52),"NIET") -> NIET
...
